Workbook
Name Planted: #REF!
Name STC13_2: #REF!

Sheet Line Item Budget
A1: Operating Income | B1: Last Fiscal Year | C1: Current Budget | D1: Next Fiscal Year
A2: Municipality | B2: 41640 | C2: 39050 | D2: 47190
A3: County | B3: 26400 | C3: 23980 | D3: 28600
A4: State | B4: 1800 | C4: 1925 | D4: 2730
A5: Donations | B5: 600 | C5: 550 | D5: 650
A6: Fines and Other Income | B6: 1560 | C6: 2310 | D6: 2730
A7: Operating Income Total | B7: =SUM(B2:B6) -> 72000 | C7: =SUM(C2:C6) -> 67815 | D7: =SUM(D2:D6) -> 81900
A9: Operating Expenditures | B9: =B1 -> Last Fiscal Year | C9: =C1 -> Current Budget | D9: =D1 -> Next Fiscal Year
A10: Salaries and Wages | B10: 28980 | C10: 27170 | D10: 33345
A11: Employee Benefits | B11: 20100 | C11: 18700 | D11: 21255
A12: Books and Periodicals | B12: 11520 | C12: 11000 | D12: 13650
A13: Staff and Board Continuing Education | B13: 2280 | C13: 2145 | D13: 2730
A14: Telecommunications | B14: 1710 | C14: 1650 | D14: 2047.5
A15: Utilities | B15: 4560 | C15: 4400 | D15: 5460
A16: Equipment Repair | B16: 1140 | C16: 1100 | D16: 1365
A17: Supplies | B17: 1710 | C17: 1650 | D17: 2047.5
A18: Operating Expenditures Total | B18: =SUM(B10:B17) -> 72000 | C18: =SUM(C10:C17) -> 67815 | D18: =SUM(D10:D17) -> 81900

Sheet Program Budget
A1: PROGRAM BUDGET FOR PUBLIC SAFETY
A3: Program | B3: Last Fiscal Year | C3: Current Budget | D3: Next Fiscal Year
A4: Law Enforcement | B4: 3770595 | C4: 4122005 | D4: =D17 -> 4731772.4
A5: Traffic Safety | B5: 1415720 | C5: 1604830 | D5: 1861680
A6: Fire Safety | B6: 2202670 | C6: 3778975 | D6: 4499125
A7: Maintenance of Public Order | B7: 459435 | C7: 510605 | D7: 592230
A8: Prevention & Control of Other Hazards | B8: 582045 | C8: 726128 | D8: 871245
A9: Total | B9: =SUM(B4:B8) -> 8430465 | C9: =SUM(C4:C8) -> 10742543 | D9: =SUM(D4:D8) -> 12556052
A11: Budget for Law Enforcement Program
A12: Subprogram | B12: Last Fiscal Year | C12: Current Budget | D12: Next Fiscal Year
A13: Police Operations | B13: 2308265 | C13: 2498640 | D13: 2876080
A14: Police Investigations | B14: 1068160 | C14: 1196645 | D14: =D25 -> 1364512.4
A15: Judgment of Non-Traffic Offenses | B15: 152260 | C15: 164820 | D15: 189715
A16: Rehabilitation of Offenders | B16: 241910 | C16: 261900 | D16: 301465
A17: Total | B17: =SUM(B13:B16) -> 3770595 | C17: =SUM(C13:C16) -> 4122005 | D17: =SUM(D13:D16) -> 4731772.4
A19: Budget for Police Investigation
A20: Program Element | B20: Last Fiscal Year | C20: Current Budget | D20: Next Fiscal Year
A21: Detective Section | B21: 542720 | C21: 604345 | D21: =B48 -> 678405.8
A22: Vice Squad | B22: 187785 | C22: 214375 | D22: =C48 -> 274279
A23: Juvenile Section | B23: 184060 | C23: 195100 | D23: =D48 -> 216354
A24: Laboratory Services | B24: 153595 | C24: 182825 | D24: =E48 -> 195474.6
A25: Totals | B25: 1068160 | C25: 1196645 | D25: =F48 -> 1364512.4
A27: Crosswalk
A28: Line-Item | B28: Detectives | C28: Vice Squad | D28: Juveniles | E28: Lab Support | F28: Subprogram Totals
A29: Personal Services
A30: Lieutenant | B30: 9450 | C30: 9450 | D30: 9450 | E30: 9450 | F30: =SUM(B30:E30) -> 37800
A31: Lab Supervisor | E31: 33600 | F31: =SUM(B31:E31) -> 33600
A32: Sergeants | B32: 30200 | C32: 30200 | D32: 30200 | F32: =SUM(B32:E32) -> 90600
A33: Inspectors | B33: 29375 | C33: 58750 | D33: 29375 | F33: =SUM(B33:E33) -> 117500
A34: Detectives | B34: 370688 | C34: 67781 | D34: 55781 | F34: =SUM(B34:E34) -> 494250
A35: Photographer | E35: 24150 | F35: =SUM(B35:E35) -> 24150
A36: Lab Technician | E36: 22680 | F36: =SUM(B36:E36) -> 22680
A37: Photo Technician | E37: 19425 | F37: =SUM(B37:E37) -> 19425
A38: Secretary | B38: 9420 | C38: 4710 | D38: 4710 | F38: =SUM(B38:E38) -> 18840
A39: Clerk-Stenographers | B39: 15799 | C39: 15799 | D39: 15799 | E39: 15799 | F39: =SUM(B39:E39) -> 63196
A40: Subtotal: Salaries | B40: =SUM(B29:B39) -> 464932 | C40: =SUM(C29:C39) -> 186690 | D40: =SUM(D29:D39) -> 145315 | E40: =SUM(E29:E39) -> 125104 | F40: =SUM(F29:F39) -> 922041
A41: Overtime @ 5% | B41: =0.05*B40 -> 23246.6 | C41: =0.05*C40 -> 9334.5 | D41: =0.05*D40 -> 7265.75 | E41: =0.05*E40 -> 6255.2 | F41: =0.05*F40 -> 46102.05
A42: Staff Benefits (35%) | B42: =B40*0.35 -> 162726.2 | C42: =C40*0.35 -> 65341.5 | D42: =D40*0.35 -> 50860.25 | E42: =E40*0.35 -> 43786.4 | F42: =F40*0.35 -> 322714.35
A43: Total Labor Costs | B43: =SUM(B40:B42) -> 650904.8 | C43: =SUM(C40:C42) -> 261366 | D43: =SUM(D40:D42) -> 203441 | E43: =SUM(E40:E42) -> 175145.6 | F43: =SUM(F40:F42) -> 1290857.4
A44: Contractual Services | B44: 10413 | C44: 4165 | D44: 4165 | E44: 2083 | F44: 20825
...

Sheet HRD Parameters
A1: HOOSIER COUNTY ROAD DEPARTMENT BASIC INFORMATION
B2: Gravel Road | C2: Paved Road | D2: Total Department
A3: Maintenance and Personal Information
A4: Supplies expenditures | B4: 41000 | C4: 180000 | D4: =SUM(B4:C4) -> 221000
A5: Miles Repaired | B5: 80 | C5: 185 | D5: =SUM(B5:C5) -> 265
A6: Cost per mile | B6: =B4/B5 -> 512.5 | C6: =C4/C5 -> 972.97297
A7: Personnel (FTE) | B7: 4 | C7: 5 | D7: =SUM(B7:C7) -> 9
A8: Days worked per employee year | B8: 225 | C8: 225
A9: State reimbursement/mile | B9: 6250 | C9: 10200
A10: Productivity (miles per person per year)
A11: Actual | B11: =B5/B7 -> 20 | C11: =C5/C7 -> 37
A12: Benchmark miles per person per year | B12: 25 | C12: 50
A13: Maintenance employee salary (inc. fringe benefits) | B13: 74000 | C13: 74000
A14: Director's salary (inc. fringe benefits) | D14: 96000
A15: Assistant's salary | D15: 61000
A16: Equipment lease
A17: Fixed rate/month | B17: 6250 | C17: 9750
A18: Variable rate per mile | B18: 725 | C18: 1100
A19: Months per year | B19: 12 | C19: 12
A20: Maintenance facility (lease rate) | D20: 210000

Sheet HRD Budget
A1: HOOSIER COUNTY ROAD DEPARTMENT
B2: Baseline | E2: Maximum Productivity
B3: Gravel | C3: Paved | D3: Total | E3: Gravel | F3: Paved | G3: Total
A4: Information on operations
A5: Miles repaired | B5: ='HRD Parameters'!B5 -> 80 | C5: ='HRD Parameters'!C5 -> 185 | D5: =SUM(B5:C5) -> 265 | E5: =B5 -> 80 | F5: =C5 -> 185 | G5: =SUM(E5:F5) -> 265
A6: Miles repaired (% of total) | B6: =B5/($B5+$C5) -> 0.30188679 | C6: =C5/($B5+$C5) -> 0.69811321 | D6: =D5/($B5+$C5) -> 1 | E6: =E5/($E5+$F5) -> 0.30188679 | F6: =F5/($E5+$F5) -> 0.69811321 | G6: =G5/($E5+$F5) -> 1
A7: Employees | B7: =B5/'HRD Parameters'!B$11 -> 4 | C7: =C5/'HRD Parameters'!C$11 -> 5 | D7: =SUM(B7:C7) -> 9 | E7: =ROUNDUP(E5/'HRD Parameters'!B$12,0) -> 4 | F7: =ROUNDUP(F5/'HRD Parameters'!C$12,0) -> 4 | G7: =SUM(E7:F7) -> 8
A8: Employees (% of total) | B8: =B7/D7 -> 0.44444444 | C8: =C7/D7 -> 0.55555556 | D8: =SUM(B8:C8) -> 1 | E8: =E7/G7 -> 0.5 | F8: =F7/G7 -> 0.5 | G8: =SUM(E8:F8) -> 1
A9: Direct costs
A10: Personnel (Employees x salary) | B10: ='HRD Parameters'!B13*'HRD Budget'!B7 -> 296000 | C10: ='HRD Parameters'!C13*'HRD Budget'!C7 -> 370000 | D10: =SUM(B10:C10) -> 666000 | E10: =E7*'HRD Parameters'!B13 -> 296000 | F10: ='HRD Parameters'!C13*'HRD Budget'!F7 -> 296000 | G10: =SUM(E10:F10) -> 592000
A11: Supplies (Miles x rate) | B11: =B5*'HRD Parameters'!B$6 -> 41000 | C11: =C5*'HRD Parameters'!C$6 -> 180000 | D11: =SUM(B11:C11) -> 221000 | E11: =E5*'HRD Parameters'!B$6 -> 41000 | F11: =F5*'HRD Parameters'!C$6 -> 180000 | G11: =SUM(E11:F11) -> 221000
A12: Equipment (fixed) | B12: ='HRD Parameters'!B17*'HRD Parameters'!B19 -> 75000 | C12: ='HRD Parameters'!C17*'HRD Parameters'!C19 -> 117000 | D12: =SUM(B12:C12) -> 192000 | E12: ='HRD Parameters'!B17*'HRD Parameters'!B19 -> 75000 | F12: ='HRD Parameters'!C17*'HRD Parameters'!C19 -> 117000 | G12: =SUM(E12:F12) -> 192000
A13: Variable (Miles x rate) | B13: =B5*'HRD Parameters'!B$18 -> 58000 | C13: =C5*'HRD Parameters'!C$18 -> 203500 | D13: =SUM(B13:C13) -> 261500 | E13: =E5*'HRD Parameters'!B$18 -> 58000 | F13: =F5*'HRD Parameters'!C$18 -> 203500 | G13: =SUM(E13:F13) -> 261500
A14: Total direct cost | B14: =SUM(B10:B13) -> 470000 | C14: =SUM(C10:C13) -> 870500 | D14: =SUM(D10:D13) -> 1340500 | E14: =SUM(E10:E13) -> 470000 | F14: =SUM(F10:F13) -> 796500 | G14: =SUM(G10:G13) -> 1266500
A15: Direct cost per mile | B15: =B14/B$5 -> 5875 | C15: =C14/C$5 -> 4705.4054 | D15: =D14/D$5 -> 5058.4906 | E15: =E14/E$5 -> 5875 | F15: =F14/F$5 -> 4305.4054 | G15: =G14/G$5 -> 4779.2453
A16: (percent of total) | B16: =B14/($B14+$C14) -> 0.35061544 | C16: =C14/($B14+$C14) -> 0.64938456 | D16: =SUM(B16:C16) -> 1 | E16: =E14/($E14+$F14) -> 0.37110146 | F16: =F14/($E14+$F14) -> 0.62889854 | G16: =SUM(E16:F16) -> 1
A17: Indirect costs
A18: Director (personnel) | B18: ='HRD Parameters'!$D14*B8 -> 42666.667 | C18: ='HRD Parameters'!$D14*C8 -> 53333.333 | D18: =SUM(B18:C18) -> 96000 | E18: ='HRD Parameters'!$D14*'HRD Budget'!E$8 -> 48000 | F18: ='HRD Parameters'!$D14*'HRD Budget'!F$8 -> 48000 | G18: =SUM(E18:F18) -> 96000
A19: Assistant (personnel) | B19: ='HRD Parameters'!$D15*B8 -> 27111.111 | C19: ='HRD Parameters'!$D15*C8 -> 33888.889 | D19: =SUM(B19:C19) -> 61000 | E19: ='HRD Parameters'!$D15*'HRD Budget'!E$8 -> 30500 | F19: ='HRD Parameters'!$D15*'HRD Budget'!F$8 -> 30500 | G19: =SUM(E19:F19) -> 61000
A20: Maintenance facility (miles) | B20: ='HRD Parameters'!$D20*B6 -> 63396.226 | C20: ='HRD Parameters'!$D20*C6 -> 146603.77 | D20: =SUM(B20:C20) -> 210000 | E20: ='HRD Parameters'!$D20*E6 -> 63396.226 | F20: ='HRD Parameters'!$D20*F6 -> 146603.77 | G20: =SUM(E20:F20) -> 210000
A21: Total indirect cost | B21: =B18+B19+B20 -> 133174 | C21: =C18+C19+C20 -> 233826 | D21: =D18+D19+D20 -> 367000 | E21: =E18+E19+E20 -> 141896.23 | F21: =F18+F19+F20 -> 225103.77 | G21: =G18+G19+G20 -> 367000
A22: Indirect cost per mile | B22: =B21/B$5 -> 1664.6751 | C22: =C21/C$5 -> 1263.9243 | D22: =D21/D$5 -> 1384.9057 | E22: =E21/E$5 -> 1773.7028 | F22: =F21/F$5 -> 1216.7772 | G22: =G21/G$5 -> 1384.9057
A23: Total cost | B23: =B21+B14 -> 603174 | C23: =C21+C14 -> 1104326 | D23: =D21+D14 -> 1707500 | E23: =E21+E14 -> 611896.23 | F23: =F21+F14 -> 1021603.8 | G23: =G21+G14 -> 1633500
A24: Total cost per mile | B24: =B23/B$5 -> 7539.6751 | C24: =C23/C$5 -> 5969.3297 | D24: =D23/D$5 -> 6443.3962 | E24: =E23/E$5 -> 7648.7028 | F24: =F23/F$5 -> 5522.1826 | G24: =G23/G$5 -> 6164.1509
A25: Total revenue | B25: =B5*'HRD Parameters'!B9 -> 500000 | C25: =C5*'HRD Parameters'!C9 -> 1887000 | D25: =SUM(B25:C25) -> 2387000 | E25: =E5*'HRD Parameters'!B9 -> 500000 | F25: =F5*'HRD Parameters'!C9 -> 1887000 | G25: =SUM(E25:F25) -> 2387000
A26: Total surplus/deficit | B26: =+B25-B23 -> -103174 | C26: =+C25-C23 -> 782674 | D26: =+D25-D23 -> 679500 | E26: =+E25-E23 -> -111896.23 | F26: =+F25-F23 -> 865396.23 | G26: =+G25-G23 -> 753500
A27: Surplus/deficit per mile | B27: =+B26/B5 -> -1289.6751 | C27: =+C26/C5 -> 4230.6703 | D27: =+D26/D5 -> 2564.1509 | E27: =+E26/E5 -> -1398.7028 | F27: =+F26/F5 -> 4677.8174 | G27: =+G26/G5 -> 2843.3962

Sheet SPEAville Police
A1: Budgeted Positions O'Neill PD
A2: Title of Position | B2: Grade | C2: Pay | E2: 2017 Actual | F2: 2018
C3: Min. | D3: Max. | F3: Requested | G3: Adopted
A4: Lieutenant | B4: 0.6 | C4: 74720 | D4: 78652 | E4: 8 | F4: 8 | G4: 8
A5: Sergeant | B5: 0.5 | C5: 65309 | D5: 68747 | E5: 20 | F5: 20 | G5: 20
A6: Patrol Officer | B6: 0.4 | C6: 44467 | D6: 63297 | E6: 119 | F6: 119 | G6: 119
A8: Positions by Tenure (2018) O'Neill PD
A9: Title of Position | B9: < 1 year | C9: 1 year | D9: 2 years | E9: 3 years | F9: 4 and more years | G9: Total
A10: Patrol Officer | B10: 10 | C10: 20 | D10: 20 | E10: 30 | F10: 39 | G10: =SUM(B10:F10) -> 119
B11: Probationary Rate | C11: Maximum Rate | D11: Total
A12: Lieutenant | B12: 2 | C12: 6 | D12: =SUM(B12:C12) -> 8
A13: Sergeant | B13: 6 | C13: 14 | D13: =SUM(B13:C13) -> 20
A15: CASE 1: No turnover and no new hires
A16: Positions by Grade and Step (2019)
A17: Title of Position | B17: =B9 -> < 1 year | C17: =C9 -> 1 year | D17: =D9 -> 2 years | E17: =E9 -> 3 years | F17: =F9 -> 4 and more years | G17: Total
A18: Patrol Officer | B18: 0 | C18: 10 | D18: 20 | E18: 20 | F18: 69 | G18: =SUM(B18:F18) -> 119
B19: Probationary Rate | C19: Maximum Rate | D19: Total
A20: Lieutenant | B20: 0 | C20: 8 | D20: =SUM(B20:C20) -> 8
A21: Sergeant | B21: 0 | C21: 20 | D21: =SUM(B21:C21) -> 20
A23: Salary Budget
A24: Title of Position | B24: =B17 -> < 1 year | C24: =C17 -> 1 year | D24: =D17 -> 2 years | E24: =E17 -> 3 years | F24: =F17 -> 4 and more years
A25: Patrol Officer | B25: 46718 | C25: 54033 | D25: 55801 | E25: 57632 | F25: 66501
B26: Probationary Rate | C26: Maximum Rate
A27: Lieutenant | B27: 80465 | C27: 84700
A28: Sergeant | B28: 70331 | C28: 75033
A30: Salary Budget
A31: Title of Position | B31: =B24 -> < 1 year | C31: =C24 -> 1 year | D31: =D24 -> 2 years | E31: =E24 -> 3 years | F31: =F24 -> 4 and more years
A32: Patrol Officer | B32: =B25*B18 -> 0 | C32: =C25*C18 -> 540330 | D32: =D25*D18 -> 1116020 | E32: =E25*E18 -> 1152640 | F32: =F25*F18 -> 4588569
B33: Probationary Rate | C33: Maximum Rate
A34: Lieutenant | B34: =B27*B20 -> 0 | C34: =C27*C20 -> 677600
A35: Sergeant | B35: =B21*B28 -> 0 | C35: =C21*C28 -> 1500660
A37: TOTAL REQUESTED BUDGET | C37: =SUM(B32:F32)+SUM(B34:C35) -> 9575819
A39: CASE 2: Incorporating historical turnover rates
A40: Positions by Grade and Step (2019)
A41: Title of Position | B41: =B17 -> < 1 year | C41: =C17 -> 1 year | D41: =D17 -> 2 years | E41: =E17 -> 3 years | F41: =F17 -> 4 and more years
A42: Patrol Officer | B42: 0.1 | C42: 0.08 | D42: 0.08 | E42: 0.07 | F42: 0.1
B43: Probationary Rate | C43: Maximum Rate
A44: Lieutenant | B44: 0.05 | C44: 0.1
A45: Sergeant | B45: 0.07 | C45: 0.05
A47: Number of Employees Leaving
...

Sheet PARK CONGESTION
A1: Parameters
A2: Population | B2: 100000
A3: v | B3: 80
A4: phi | B4: 30
A5: a | B5: 200
A6: b | B6: 0.05
A8: Park Size (G) | B8: 300
A9: Cost | B9: =B5*B8+B6*B8^2 -> 64500
A10: Tax per Person | B10: =B9/B2 -> 0.645
A12: Benefit per Person | B12: =B3*LN(B8)-B4*B2/B8 -> -9543.6974
A13: Total Surplus | B13: =B2*B12-B9 -> -9.5443424e+08

Sheet STATE TAXE REFORM
A1: Case Study: State Taxes
A2: Household | B2: A | C2: B | D2: C | E2: D | F2: E | G2: F | H2: G | I2: H | J2: I | K2: J
A3: Alpha Gasoline | B3: 0.5 | C3: =B3-0.03 -> 0.47 | D3: =C3-0.03 -> 0.44 | E3: =D3-0.03 -> 0.41 | F3: =E3-0.03 -> 0.38 | G3: =F3-0.03 -> 0.35 | H3: =G3-0.03 -> 0.32 | I3: =H3-0.03 -> 0.29 | J3: =I3-0.03 -> 0.26 | K3: =J3-0.03 -> 0.23
A4: Alpha Food | B4: 0.4 | C4: =B4-0.01 -> 0.39 | D4: =C4-0.01 -> 0.38 | E4: =D4-0.01 -> 0.37 | F4: =E4-0.01 -> 0.36 | G4: =F4-0.01 -> 0.35 | H4: =G4-0.01 -> 0.34 | I4: =H4-0.01 -> 0.33 | J4: =I4-0.01 -> 0.32 | K4: =J4-0.01 -> 0.31
A5: Alpha Other Goods | B5: =1-B4-B3 -> 0.1 | C5: =1-C4-C3 -> 0.14 | D5: =1-D4-D3 -> 0.18 | E5: =1-E4-E3 -> 0.22 | F5: =1-F4-F3 -> 0.26 | G5: =1-G4-G3 -> 0.3 | H5: =1-H4-H3 -> 0.34 | I5: =1-I4-I3 -> 0.38 | ... K5: =1-K4-K3 -> 0.46
A6: Income Before State Income Tax | B6: 7000 | C6: 20000 | D6: 30000 | E6: 41000 | F6: 54000 | G6: 70000 | H6: 90000 | I6: 115000 | J6: 155000 | K6: 300000
A7: State Income Tax Rate (%) | B7: 0.03 | C7: 0.03 | D7: 0.03 | E7: 0.03 | F7: 0.03 | G7: 0.03 | H7: 0.03 | I7: 0.03 | J7: 0.03 | K7: 0.03
A8: Sales Tax Rate (%) | B8: 0.05 | C8: 0.05 | D8: 0.05 | E8: 0.05 | F8: 0.05 | G8: 0.05 | H8: 0.05 | I8: 0.05 | J8: 0.05 | K8: 0.05
A9: Gasoline Tax Rate ($)
A10: Wholesale Price: Gasoline ($)
A11: Wholesale Price: Food ($)
A12: Wholesale Price: Other Goods ($)
A13: State Income Tax Revenue ($) | L13: =SUM(B13:K13) -> 0
A14: Income After State Income Tax ($)
A15: Gasoline Retail Price ($)
A16: Gasoline Quantity Demanded
A17: Gasoline Total Expenditure ($)
A18: Gasoline Tax Expenditure ($) | L18: =SUM(B18:K18) -> 0
A19: Gasoline Effective Tax Rate (%)
A20: Food Retail Price ($)
A21: Food Quantity Demanded
A22: Food Total Expenditure ($)
A23: Food Tax Expenditure ($) | L23: =SUM(B23:K23) -> 0
A24: Food Effective Tax Rate (%)
A25: Other Goods Retail Price ($)
A26: Other Goods Quantity Demanded
A27: Other Goods Total Expenditure ($)
A28: Other Goods Tax Expenditure ($) | L28: =SUM(B28:K28) -> 0
A29: Other Goods Effective Tax Rate (%)
A30: Total Tax Expenditures ($) | L30: =L13+L28+L23+L18 -> 0
A31: Effective Tax Rate All Taxes (%)
